Error in API call.
POI index: 36, review ID: 736775889, row index: 0, time: 2020-02-10 11:56:52.244219
Traceback (most recent call last):
  File "/home/zyf0717/git/STB_social_media_analytics/tripadvisor/sentiment_scorer.py", line 185, in score_sentiments_1_poi
    self.get_api_response()
  File "/home/zyf0717/git/STB_social_media_analytics/tripadvisor/sentiment_scorer.py", line 245, in get_api_response
    keywords=KeywordsOptions(emotion=True, sentiment=True, limit=10000)
  File "/home/zyf0717/anaconda3/envs/crawl/lib/python3.7/site-packages/ibm_watson/natural_language_understanding_v1.py", line 186, in analyze
    response = self.send(request)
  File "/home/zyf0717/anaconda3/envs/crawl/lib/python3.7/site-packages/ibm_cloud_sdk_core/base_service.py", line 157, in send
    response.status_code, error_message, http_response=response)
ibm_cloud_sdk_core.api_exception.ApiException: Error: Forbidden, Code: 403

API key 0 has been exhausted.

Error in API call.
POI index: 36, review ID: 736775889, row index: 0, time: 2020-02-10 11:56:53.353449
Traceback (most recent call last):
  File "/home/zyf0717/git/STB_social_media_analytics/tripadvisor/sentiment_scorer.py", line 185, in score_sentiments_1_poi
    self.get_api_response()
  File "/home/zyf0717/git/STB_social_media_analytics/tripadvisor/sentiment_scorer.py", line 245, in get_api_response
    keywords=KeywordsOptions(emotion=True, sentiment=True, limit=10000)
  File "/home/zyf0717/anaconda3/envs/crawl/lib/python3.7/site-packages/ibm_watson/natural_language_understanding_v1.py", line 186, in analyze
    response = self.send(request)
  File "/home/zyf0717/anaconda3/envs/crawl/lib/python3.7/site-packages/ibm_cloud_sdk_core/base_service.py", line 157, in send
    response.status_code, error_message, http_response=response)
ibm_cloud_sdk_core.api_exception.ApiException: Error: Forbidden, Code: 403

API key 1 has been exhausted.

Error in API call.
POI index: 36, review ID: 736775889, row index: 0, time: 2020-02-10 11:56:55.678214
Traceback (most recent call last):
  File "/home/zyf0717/git/STB_social_media_analytics/tripadvisor/sentiment_scorer.py", line 185, in score_sentiments_1_poi
    self.get_api_response()
  File "/home/zyf0717/git/STB_social_media_analytics/tripadvisor/sentiment_scorer.py", line 245, in get_api_response
    keywords=KeywordsOptions(emotion=True, sentiment=True, limit=10000)
  File "/home/zyf0717/anaconda3/envs/crawl/lib/python3.7/site-packages/ibm_watson/natural_language_understanding_v1.py", line 186, in analyze
    response = self.send(request)
  File "/home/zyf0717/anaconda3/envs/crawl/lib/python3.7/site-packages/ibm_cloud_sdk_core/base_service.py", line 157, in send
    response.status_code, error_message, http_response=response)
ibm_cloud_sdk_core.api_exception.ApiException: Error: Forbidden, Code: 403

API key 2 has been exhausted.

Error in API call.
POI index: 40, review ID: 483581626, row index: 30, time: 2020-02-10 12:24:52.368542
Traceback (most recent call last):
  File "/home/zyf0717/anaconda3/envs/crawl/lib/python3.7/site-packages/urllib3/connection.py", line 157, in _new_conn
    (self._dns_host, self.port), self.timeout, **extra_kw
  File "/home/zyf0717/anaconda3/envs/crawl/lib/python3.7/site-packages/urllib3/util/connection.py", line 84, in create_connection
    raise err
  File "/home/zyf0717/anaconda3/envs/crawl/lib/python3.7/site-packages/urllib3/util/connection.py", line 74, in create_connection
    sock.connect(sa)
OSError: [Errno 101] Network is unreachable

During handling of the above exception, another exception occurred:

Traceback (most recent call last):
  File "/home/zyf0717/anaconda3/envs/crawl/lib/python3.7/site-packages/urllib3/connectionpool.py", line 672, in urlopen
    chunked=chunked,
  File "/home/zyf0717/anaconda3/envs/crawl/lib/python3.7/site-packages/urllib3/connectionpool.py", line 376, in _make_request
    self._validate_conn(conn)
  File "/home/zyf0717/anaconda3/envs/crawl/lib/python3.7/site-packages/urllib3/connectionpool.py", line 994, in _validate_conn
    conn.connect()
  File "/home/zyf0717/anaconda3/envs/crawl/lib/python3.7/site-packages/urllib3/connection.py", line 334, in connect
    conn = self._new_conn()
  File "/home/zyf0717/anaconda3/envs/crawl/lib/python3.7/site-packages/urllib3/connection.py", line 169, in _new_conn
    self, "Failed to establish a new connection: %s" % e
urllib3.exceptions.NewConnectionError: <urllib3.connection.VerifiedHTTPSConnection object at 0x7f345cede850>: Failed to establish a new connection: [Errno 101] Network is unreachable

During handling of the above exception, another exception occurred:

Traceback (most recent call last):
  File "/home/zyf0717/anaconda3/envs/crawl/lib/python3.7/site-packages/requests/adapters.py", line 449, in send
    timeout=timeout
  File "/home/zyf0717/anaconda3/envs/crawl/lib/python3.7/site-packages/urllib3/connectionpool.py", line 720, in urlopen
    method, url, error=e, _pool=self, _stacktrace=sys.exc_info()[2]
  File "/home/zyf0717/anaconda3/envs/crawl/lib/python3.7/site-packages/urllib3/util/retry.py", line 436, in increment
    raise MaxRetryError(_pool, url, error or ResponseError(cause))
urllib3.exceptions.MaxRetryError: HTTPSConnectionPool(host='gateway.watsonplatform.net', port=443): Max retries exceeded with url: /natural-language-understanding/api/v1/analyze?version=2019-07-12/v1/analyze&version=2019-07-12 (Caused by NewConnectionError('<urllib3.connection.VerifiedHTTPSConnection object at 0x7f345cede850>: Failed to establish a new connection: [Errno 101] Network is unreachable'))

During handling of the above exception, another exception occurred:

Traceback (most recent call last):
  File "/home/zyf0717/git/STB_social_media_analytics/tripadvisor/sentiment_scorer.py", line 185, in score_sentiments_1_poi
    self.get_api_response()
  File "/home/zyf0717/git/STB_social_media_analytics/tripadvisor/sentiment_scorer.py", line 245, in get_api_response
    keywords=KeywordsOptions(emotion=True, sentiment=True, limit=10000)
  File "/home/zyf0717/anaconda3/envs/crawl/lib/python3.7/site-packages/ibm_watson/natural_language_understanding_v1.py", line 186, in analyze
    response = self.send(request)
  File "/home/zyf0717/anaconda3/envs/crawl/lib/python3.7/site-packages/ibm_cloud_sdk_core/base_service.py", line 136, in send
    response = requests.request(**request, cookies=self.jar, **kwargs)
  File "/home/zyf0717/anaconda3/envs/crawl/lib/python3.7/site-packages/requests/api.py", line 60, in request
    return session.request(method=method, url=url, **kwargs)
  File "/home/zyf0717/anaconda3/envs/crawl/lib/python3.7/site-packages/requests/sessions.py", line 533, in request
    resp = self.send(prep, **send_kwargs)
  File "/home/zyf0717/anaconda3/envs/crawl/lib/python3.7/site-packages/requests/sessions.py", line 646, in send
    r = adapter.send(request, **kwargs)
  File "/home/zyf0717/anaconda3/envs/crawl/lib/python3.7/site-packages/requests/adapters.py", line 516, in send
    raise ConnectionError(e, request=request)
requests.exceptions.ConnectionError: HTTPSConnectionPool(host='gateway.watsonplatform.net', port=443): Max retries exceeded with url: /natural-language-understanding/api/v1/analyze?version=2019-07-12/v1/analyze&version=2019-07-12 (Caused by NewConnectionError('<urllib3.connection.VerifiedHTTPSConnection object at 0x7f345cede850>: Failed to establish a new connection: [Errno 101] Network is unreachable'))

Error in API call.
POI index: 42, review ID: 472331269, row index: 146, time: 2020-02-10 12:33:33.816710
Traceback (most recent call last):
  File "/home/zyf0717/git/STB_social_media_analytics/tripadvisor/sentiment_scorer.py", line 185, in score_sentiments_1_poi
    self.get_api_response()
  File "/home/zyf0717/git/STB_social_media_analytics/tripadvisor/sentiment_scorer.py", line 245, in get_api_response
    keywords=KeywordsOptions(emotion=True, sentiment=True, limit=10000)
  File "/home/zyf0717/anaconda3/envs/crawl/lib/python3.7/site-packages/ibm_watson/natural_language_understanding_v1.py", line 186, in analyze
    response = self.send(request)
  File "/home/zyf0717/anaconda3/envs/crawl/lib/python3.7/site-packages/ibm_cloud_sdk_core/base_service.py", line 157, in send
    response.status_code, error_message, http_response=response)
ibm_cloud_sdk_core.api_exception.ApiException: Error: Forbidden, Code: 403

API key 3 has been exhausted.

