98, Fountainof Wealth, page: 1, 2020-02-14 17:05:49.433203
Traceback (most recent call last):
  File "/home/jia/Desktop/git/STB_social_media_analytics/experimentation/jiaxin_experiment/ctrip/Ctrip_crawler.py", line 294, in crawl_pois
    self.crawl_reviews()
  File "/home/jia/Desktop/git/STB_social_media_analytics/experimentation/jiaxin_experiment/ctrip/Ctrip_crawler.py", line 447, in crawl_reviews
    self.crawl_reviews_1_page(self.current_poi_index)
  File "/home/jia/Desktop/git/STB_social_media_analytics/experimentation/jiaxin_experiment/ctrip/Ctrip_crawler.py", line 558, in crawl_reviews_1_page
    next_page_button = self.driver.find_elements_by_xpath('//a[@class="nextpage"]')
  File "/home/jia/anaconda3/envs/crawl/lib/python3.7/site-packages/selenium/webdriver/remote/webdriver.py", line 410, in find_elements_by_xpath
    return self.find_elements(by=By.XPATH, value=xpath)
  File "/home/jia/anaconda3/envs/crawl/lib/python3.7/site-packages/selenium/webdriver/remote/webdriver.py", line 1007, in find_elements
    'value': value})['value'] or []
  File "/home/jia/anaconda3/envs/crawl/lib/python3.7/site-packages/selenium/webdriver/remote/webdriver.py", line 321, in execute
    self.error_handler.check_response(response)
  File "/home/jia/anaconda3/envs/crawl/lib/python3.7/site-packages/selenium/webdriver/remote/errorhandler.py", line 242, in check_response
    raise exception_class(message, screen, stacktrace)
selenium.common.exceptions.WebDriverException: Message: chrome not reachable
  (Session info: chrome=79.0.3945.130)


