POI index: 2, Review ID: 740129353, 2020-02-07 09:31:06.897700
Traceback (most recent call last):
  File "/home/zyf0717/git/STB_social_media_analytics/tripadvisor/sentiment_scorer.py", line 152, in score_sentiments_1_poi
    self.get_api_response()
  File "/home/zyf0717/git/STB_social_media_analytics/tripadvisor/sentiment_scorer.py", line 199, in get_api_response
    keywords=KeywordsOptions(emotion=True, sentiment=True, limit=10000)
  File "/home/zyf0717/anaconda3/envs/crawl/lib/python3.7/site-packages/ibm_watson/natural_language_understanding_v1.py", line 186, in analyze
    response = self.send(request)
  File "/home/zyf0717/anaconda3/envs/crawl/lib/python3.7/site-packages/ibm_cloud_sdk_core/base_service.py", line 157, in send
    response.status_code, error_message, http_response=response)
ibm_cloud_sdk_core.api_exception.ApiException: Error: Forbidden, Code: 403

POI index: 2, Review ID: 529889129, 2020-02-07 12:02:22.539978
Traceback (most recent call last):
  File "/home/zyf0717/git/STB_social_media_analytics/tripadvisor/sentiment_scorer.py", line 152, in score_sentiments_1_poi
    self.get_api_response()
  File "/home/zyf0717/git/STB_social_media_analytics/tripadvisor/sentiment_scorer.py", line 199, in get_api_response
    keywords=KeywordsOptions(emotion=True, sentiment=True, limit=10000)
  File "/home/zyf0717/anaconda3/envs/crawl/lib/python3.7/site-packages/ibm_watson/natural_language_understanding_v1.py", line 186, in analyze
    response = self.send(request)
  File "/home/zyf0717/anaconda3/envs/crawl/lib/python3.7/site-packages/ibm_cloud_sdk_core/base_service.py", line 157, in send
    response.status_code, error_message, http_response=response)
ibm_cloud_sdk_core.api_exception.ApiException: Error: Forbidden, Code: 403

POI index: 2, Review ID: 446882420, 2020-02-07 12:13:29.889623
Traceback (most recent call last):
  File "/home/zyf0717/git/STB_social_media_analytics/tripadvisor/sentiment_scorer.py", line 175, in score_sentiments_1_poi
    self.write_to_csv()
  File "/home/zyf0717/git/STB_social_media_analytics/tripadvisor/sentiment_scorer.py", line 226, in write_to_csv
    if self.entities_df.shape[1] != 0:
AttributeError: 'NoneType' object has no attribute 'shape'

POI index: 2, Review ID: 446882420, 2020-02-07 12:13:35.179101
Traceback (most recent call last):
  File "/home/zyf0717/git/STB_social_media_analytics/tripadvisor/sentiment_scorer.py", line 175, in score_sentiments_1_poi
    self.write_to_csv()
  File "/home/zyf0717/git/STB_social_media_analytics/tripadvisor/sentiment_scorer.py", line 226, in write_to_csv
    if self.entities_df.shape[1] != 0:
AttributeError: 'NoneType' object has no attribute 'shape'

POI index: 2, Review ID: 446882420, 2020-02-07 12:13:40.173363
Traceback (most recent call last):
  File "/home/zyf0717/git/STB_social_media_analytics/tripadvisor/sentiment_scorer.py", line 175, in score_sentiments_1_poi
    self.write_to_csv()
  File "/home/zyf0717/git/STB_social_media_analytics/tripadvisor/sentiment_scorer.py", line 226, in write_to_csv
    if self.entities_df.shape[1] != 0:
AttributeError: 'NoneType' object has no attribute 'shape'

POI index: 2, Review ID: 446882420, 2020-02-07 12:13:49.924181
Traceback (most recent call last):
  File "/home/zyf0717/git/STB_social_media_analytics/tripadvisor/sentiment_scorer.py", line 175, in score_sentiments_1_poi
    self.write_to_csv()
  File "/home/zyf0717/git/STB_social_media_analytics/tripadvisor/sentiment_scorer.py", line 226, in write_to_csv
    if self.entities_df.shape[1] != 0:
AttributeError: 'NoneType' object has no attribute 'shape'

POI index: 2, Review ID: 446882420, 2020-02-07 12:13:54.945538
Traceback (most recent call last):
  File "/home/zyf0717/git/STB_social_media_analytics/tripadvisor/sentiment_scorer.py", line 175, in score_sentiments_1_poi
    self.write_to_csv()
  File "/home/zyf0717/git/STB_social_media_analytics/tripadvisor/sentiment_scorer.py", line 226, in write_to_csv
    if self.entities_df.shape[1] != 0:
AttributeError: 'NoneType' object has no attribute 'shape'

POI index: 3, Review ID: 372559200, 2020-02-07 18:00:10.853687
Traceback (most recent call last):
  File "/home/zyf0717/git/STB_social_media_analytics/tripadvisor/sentiment_scorer.py", line 172, in score_sentiments_1_poi
    self.current_row_index
  File "/home/zyf0717/git/STB_social_media_analytics/tripadvisor/sentiment_scorer.py", line 220, in get_api_response
    self.current_api_response = self.nlu.analyze(
  File "/home/zyf0717/anaconda3/envs/crawl/lib/python3.7/site-packages/ibm_watson/natural_language_understanding_v1.py", line 186, in analyze
    response = self.send(request)
  File "/home/zyf0717/anaconda3/envs/crawl/lib/python3.7/site-packages/ibm_cloud_sdk_core/base_service.py", line 157, in send
    response.status_code, error_message, http_response=response)
ibm_cloud_sdk_core.api_exception.ApiException: Error: <HTML><HEAD>
<TITLE>Service Unavailable</TITLE>
</HEAD><BODY>
<H1>Service Unavailable - Zero size object</H1>
The server is temporarily unable to service your request.  Please try again
later.<P>
Reference&#32;&#35;15&#46;21781bb8&#46;1581069610&#46;df5b8bf
</BODY></HTML>
, Code: 503

POI index: 3, review ID: 374950992, row index: 6419, time: 2020-02-08 09:37:39.031497
Traceback (most recent call last):
  File "/home/zyf0717/anaconda3/envs/crawl/lib/python3.7/site-packages/urllib3/connection.py", line 157, in _new_conn
    (self._dns_host, self.port), self.timeout, **extra_kw
  File "/home/zyf0717/anaconda3/envs/crawl/lib/python3.7/site-packages/urllib3/util/connection.py", line 61, in create_connection
    for res in socket.getaddrinfo(host, port, family, socket.SOCK_STREAM):
  File "/home/zyf0717/anaconda3/envs/crawl/lib/python3.7/socket.py", line 748, in getaddrinfo
    for res in _socket.getaddrinfo(host, port, family, type, proto, flags):
socket.gaierror: [Errno -3] Temporary failure in name resolution

During handling of the above exception, another exception occurred:

Traceback (most recent call last):
  File "/home/zyf0717/anaconda3/envs/crawl/lib/python3.7/site-packages/urllib3/connectionpool.py", line 672, in urlopen
    chunked=chunked,
  File "/home/zyf0717/anaconda3/envs/crawl/lib/python3.7/site-packages/urllib3/connectionpool.py", line 376, in _make_request
    self._validate_conn(conn)
  File "/home/zyf0717/anaconda3/envs/crawl/lib/python3.7/site-packages/urllib3/connectionpool.py", line 994, in _validate_conn
    conn.connect()
  File "/home/zyf0717/anaconda3/envs/crawl/lib/python3.7/site-packages/urllib3/connection.py", line 334, in connect
    conn = self._new_conn()
  File "/home/zyf0717/anaconda3/envs/crawl/lib/python3.7/site-packages/urllib3/connection.py", line 169, in _new_conn
    self, "Failed to establish a new connection: %s" % e
urllib3.exceptions.NewConnectionError: <urllib3.connection.VerifiedHTTPSConnection object at 0x7f6fd1663cd0>: Failed to establish a new connection: [Errno -3] Temporary failure in name resolution

During handling of the above exception, another exception occurred:

Traceback (most recent call last):
  File "/home/zyf0717/anaconda3/envs/crawl/lib/python3.7/site-packages/requests/adapters.py", line 449, in send
    timeout=timeout
  File "/home/zyf0717/anaconda3/envs/crawl/lib/python3.7/site-packages/urllib3/connectionpool.py", line 720, in urlopen
    method, url, error=e, _pool=self, _stacktrace=sys.exc_info()[2]
  File "/home/zyf0717/anaconda3/envs/crawl/lib/python3.7/site-packages/urllib3/util/retry.py", line 436, in increment
    raise MaxRetryError(_pool, url, error or ResponseError(cause))
urllib3.exceptions.MaxRetryError: HTTPSConnectionPool(host='gateway.watsonplatform.net', port=443): Max retries exceeded with url: /natural-language-understanding/api/v1/analyze?version=2019-07-12/v1/analyze&version=2019-07-12 (Caused by NewConnectionError('<urllib3.connection.VerifiedHTTPSConnection object at 0x7f6fd1663cd0>: Failed to establish a new connection: [Errno -3] Temporary failure in name resolution'))

During handling of the above exception, another exception occurred:

Traceback (most recent call last):
  File "/home/zyf0717/git/STB_social_media_analytics/tripadvisor/sentiment_scorer.py", line 176, in score_sentiments_1_poi
    self.get_api_response()
  File "/home/zyf0717/git/STB_social_media_analytics/tripadvisor/sentiment_scorer.py", line 226, in get_api_response
    features=Features(
  File "/home/zyf0717/anaconda3/envs/crawl/lib/python3.7/site-packages/ibm_watson/natural_language_understanding_v1.py", line 186, in analyze
    response = self.send(request)
  File "/home/zyf0717/anaconda3/envs/crawl/lib/python3.7/site-packages/ibm_cloud_sdk_core/base_service.py", line 136, in send
    response = requests.request(**request, cookies=self.jar, **kwargs)
  File "/home/zyf0717/anaconda3/envs/crawl/lib/python3.7/site-packages/requests/api.py", line 60, in request
    return session.request(method=method, url=url, **kwargs)
  File "/home/zyf0717/anaconda3/envs/crawl/lib/python3.7/site-packages/requests/sessions.py", line 533, in request
    resp = self.send(prep, **send_kwargs)
  File "/home/zyf0717/anaconda3/envs/crawl/lib/python3.7/site-packages/requests/sessions.py", line 646, in send
    r = adapter.send(request, **kwargs)
  File "/home/zyf0717/anaconda3/envs/crawl/lib/python3.7/site-packages/requests/adapters.py", line 516, in send
    raise ConnectionError(e, request=request)
requests.exceptions.ConnectionError: HTTPSConnectionPool(host='gateway.watsonplatform.net', port=443): Max retries exceeded with url: /natural-language-understanding/api/v1/analyze?version=2019-07-12/v1/analyze&version=2019-07-12 (Caused by NewConnectionError('<urllib3.connection.VerifiedHTTPSConnection object at 0x7f6fd1663cd0>: Failed to establish a new connection: [Errno -3] Temporary failure in name resolution'))

