POI index: 2, Review ID: 740129353, 2020-02-07 09:31:06.897700
Traceback (most recent call last):
  File "/home/zyf0717/git/STB_social_media_analytics/tripadvisor/sentiment_scorer.py", line 152, in score_sentiments_1_poi
    self.get_api_response()
  File "/home/zyf0717/git/STB_social_media_analytics/tripadvisor/sentiment_scorer.py", line 199, in get_api_response
    keywords=KeywordsOptions(emotion=True, sentiment=True, limit=10000)
  File "/home/zyf0717/anaconda3/envs/crawl/lib/python3.7/site-packages/ibm_watson/natural_language_understanding_v1.py", line 186, in analyze
    response = self.send(request)
  File "/home/zyf0717/anaconda3/envs/crawl/lib/python3.7/site-packages/ibm_cloud_sdk_core/base_service.py", line 157, in send
    response.status_code, error_message, http_response=response)
ibm_cloud_sdk_core.api_exception.ApiException: Error: Forbidden, Code: 403

POI index: 2, Review ID: 529889129, 2020-02-07 12:02:22.539978
Traceback (most recent call last):
  File "/home/zyf0717/git/STB_social_media_analytics/tripadvisor/sentiment_scorer.py", line 152, in score_sentiments_1_poi
    self.get_api_response()
  File "/home/zyf0717/git/STB_social_media_analytics/tripadvisor/sentiment_scorer.py", line 199, in get_api_response
    keywords=KeywordsOptions(emotion=True, sentiment=True, limit=10000)
  File "/home/zyf0717/anaconda3/envs/crawl/lib/python3.7/site-packages/ibm_watson/natural_language_understanding_v1.py", line 186, in analyze
    response = self.send(request)
  File "/home/zyf0717/anaconda3/envs/crawl/lib/python3.7/site-packages/ibm_cloud_sdk_core/base_service.py", line 157, in send
    response.status_code, error_message, http_response=response)
ibm_cloud_sdk_core.api_exception.ApiException: Error: Forbidden, Code: 403

POI index: 2, Review ID: 446882420, 2020-02-07 12:13:29.889623
Traceback (most recent call last):
  File "/home/zyf0717/git/STB_social_media_analytics/tripadvisor/sentiment_scorer.py", line 175, in score_sentiments_1_poi
    self.write_to_csv()
  File "/home/zyf0717/git/STB_social_media_analytics/tripadvisor/sentiment_scorer.py", line 226, in write_to_csv
    if self.entities_df.shape[1] != 0:
AttributeError: 'NoneType' object has no attribute 'shape'

POI index: 2, Review ID: 446882420, 2020-02-07 12:13:35.179101
Traceback (most recent call last):
  File "/home/zyf0717/git/STB_social_media_analytics/tripadvisor/sentiment_scorer.py", line 175, in score_sentiments_1_poi
    self.write_to_csv()
  File "/home/zyf0717/git/STB_social_media_analytics/tripadvisor/sentiment_scorer.py", line 226, in write_to_csv
    if self.entities_df.shape[1] != 0:
AttributeError: 'NoneType' object has no attribute 'shape'

POI index: 2, Review ID: 446882420, 2020-02-07 12:13:40.173363
Traceback (most recent call last):
  File "/home/zyf0717/git/STB_social_media_analytics/tripadvisor/sentiment_scorer.py", line 175, in score_sentiments_1_poi
    self.write_to_csv()
  File "/home/zyf0717/git/STB_social_media_analytics/tripadvisor/sentiment_scorer.py", line 226, in write_to_csv
    if self.entities_df.shape[1] != 0:
AttributeError: 'NoneType' object has no attribute 'shape'

POI index: 2, Review ID: 446882420, 2020-02-07 12:13:49.924181
Traceback (most recent call last):
  File "/home/zyf0717/git/STB_social_media_analytics/tripadvisor/sentiment_scorer.py", line 175, in score_sentiments_1_poi
    self.write_to_csv()
  File "/home/zyf0717/git/STB_social_media_analytics/tripadvisor/sentiment_scorer.py", line 226, in write_to_csv
    if self.entities_df.shape[1] != 0:
AttributeError: 'NoneType' object has no attribute 'shape'

POI index: 2, Review ID: 446882420, 2020-02-07 12:13:54.945538
Traceback (most recent call last):
  File "/home/zyf0717/git/STB_social_media_analytics/tripadvisor/sentiment_scorer.py", line 175, in score_sentiments_1_poi
    self.write_to_csv()
  File "/home/zyf0717/git/STB_social_media_analytics/tripadvisor/sentiment_scorer.py", line 226, in write_to_csv
    if self.entities_df.shape[1] != 0:
AttributeError: 'NoneType' object has no attribute 'shape'

POI index: 3, Review ID: 372559200, 2020-02-07 18:00:10.853687
Traceback (most recent call last):
  File "/home/zyf0717/git/STB_social_media_analytics/tripadvisor/sentiment_scorer.py", line 172, in score_sentiments_1_poi
    self.current_row_index
  File "/home/zyf0717/git/STB_social_media_analytics/tripadvisor/sentiment_scorer.py", line 220, in get_api_response
    self.current_api_response = self.nlu.analyze(
  File "/home/zyf0717/anaconda3/envs/crawl/lib/python3.7/site-packages/ibm_watson/natural_language_understanding_v1.py", line 186, in analyze
    response = self.send(request)
  File "/home/zyf0717/anaconda3/envs/crawl/lib/python3.7/site-packages/ibm_cloud_sdk_core/base_service.py", line 157, in send
    response.status_code, error_message, http_response=response)
ibm_cloud_sdk_core.api_exception.ApiException: Error: <HTML><HEAD>
<TITLE>Service Unavailable</TITLE>
</HEAD><BODY>
<H1>Service Unavailable - Zero size object</H1>
The server is temporarily unable to service your request.  Please try again
later.<P>
Reference&#32;&#35;15&#46;21781bb8&#46;1581069610&#46;df5b8bf
</BODY></HTML>
, Code: 503

