Error in API call.
POI index: 9, review ID: 740910650, row index: 0, time: 2020-02-08 23:36:52.458823
Traceback (most recent call last):
  File "/home/zyf0717/git/STB_social_media_analytics/tripadvisor/sentiment_scorer.py", line 179, in score_sentiments_1_poi
    self.get_api_response()
  File "/home/zyf0717/git/STB_social_media_analytics/tripadvisor/sentiment_scorer.py", line 239, in get_api_response
    keywords=KeywordsOptions(emotion=True, sentiment=True, limit=10000)
  File "/home/zyf0717/anaconda3/envs/crawl/lib/python3.7/site-packages/ibm_watson/natural_language_understanding_v1.py", line 186, in analyze
    response = self.send(request)
  File "/home/zyf0717/anaconda3/envs/crawl/lib/python3.7/site-packages/ibm_cloud_sdk_core/base_service.py", line 157, in send
    response.status_code, error_message, http_response=response)
ibm_cloud_sdk_core.api_exception.ApiException: Error: Forbidden, Code: 403

API key 0 has been exhausted.
Error in API call.
POI index: 9, review ID: 740910650, row index: 0, time: 2020-02-08 23:36:59.421821
Traceback (most recent call last):
  File "/home/zyf0717/git/STB_social_media_analytics/tripadvisor/sentiment_scorer.py", line 179, in score_sentiments_1_poi
    self.get_api_response()
  File "/home/zyf0717/git/STB_social_media_analytics/tripadvisor/sentiment_scorer.py", line 239, in get_api_response
    keywords=KeywordsOptions(emotion=True, sentiment=True, limit=10000)
  File "/home/zyf0717/anaconda3/envs/crawl/lib/python3.7/site-packages/ibm_watson/natural_language_understanding_v1.py", line 186, in analyze
    response = self.send(request)
  File "/home/zyf0717/anaconda3/envs/crawl/lib/python3.7/site-packages/ibm_cloud_sdk_core/base_service.py", line 157, in send
    response.status_code, error_message, http_response=response)
ibm_cloud_sdk_core.api_exception.ApiException: Error: Forbidden, Code: 403

API key 1 has been exhausted.
Error in API call.
POI index: 9, review ID: 740910650, row index: 0, time: 2020-02-08 23:37:05.975606
Traceback (most recent call last):
  File "/home/zyf0717/git/STB_social_media_analytics/tripadvisor/sentiment_scorer.py", line 179, in score_sentiments_1_poi
    self.get_api_response()
  File "/home/zyf0717/git/STB_social_media_analytics/tripadvisor/sentiment_scorer.py", line 239, in get_api_response
    keywords=KeywordsOptions(emotion=True, sentiment=True, limit=10000)
  File "/home/zyf0717/anaconda3/envs/crawl/lib/python3.7/site-packages/ibm_watson/natural_language_understanding_v1.py", line 186, in analyze
    response = self.send(request)
  File "/home/zyf0717/anaconda3/envs/crawl/lib/python3.7/site-packages/ibm_cloud_sdk_core/base_service.py", line 157, in send
    response.status_code, error_message, http_response=response)
ibm_cloud_sdk_core.api_exception.ApiException: Error: Forbidden, Code: 403

API key 2 has been exhausted.
Error in API call.
POI index: 10, review ID: 469735750, row index: 597, time: 2020-02-09 00:24:59.336292
Traceback (most recent call last):
  File "/home/zyf0717/anaconda3/envs/crawl/lib/python3.7/site-packages/urllib3/connection.py", line 157, in _new_conn
    (self._dns_host, self.port), self.timeout, **extra_kw
  File "/home/zyf0717/anaconda3/envs/crawl/lib/python3.7/site-packages/urllib3/util/connection.py", line 61, in create_connection
    for res in socket.getaddrinfo(host, port, family, socket.SOCK_STREAM):
  File "/home/zyf0717/anaconda3/envs/crawl/lib/python3.7/socket.py", line 748, in getaddrinfo
    for res in _socket.getaddrinfo(host, port, family, type, proto, flags):
socket.gaierror: [Errno -3] Temporary failure in name resolution

During handling of the above exception, another exception occurred:

Traceback (most recent call last):
  File "/home/zyf0717/anaconda3/envs/crawl/lib/python3.7/site-packages/urllib3/connectionpool.py", line 672, in urlopen
    chunked=chunked,
  File "/home/zyf0717/anaconda3/envs/crawl/lib/python3.7/site-packages/urllib3/connectionpool.py", line 376, in _make_request
    self._validate_conn(conn)
  File "/home/zyf0717/anaconda3/envs/crawl/lib/python3.7/site-packages/urllib3/connectionpool.py", line 994, in _validate_conn
    conn.connect()
  File "/home/zyf0717/anaconda3/envs/crawl/lib/python3.7/site-packages/urllib3/connection.py", line 334, in connect
    conn = self._new_conn()
  File "/home/zyf0717/anaconda3/envs/crawl/lib/python3.7/site-packages/urllib3/connection.py", line 169, in _new_conn
    self, "Failed to establish a new connection: %s" % e
urllib3.exceptions.NewConnectionError: <urllib3.connection.VerifiedHTTPSConnection object at 0x7fc44ac9cb90>: Failed to establish a new connection: [Errno -3] Temporary failure in name resolution

During handling of the above exception, another exception occurred:

Traceback (most recent call last):
  File "/home/zyf0717/anaconda3/envs/crawl/lib/python3.7/site-packages/requests/adapters.py", line 449, in send
    timeout=timeout
  File "/home/zyf0717/anaconda3/envs/crawl/lib/python3.7/site-packages/urllib3/connectionpool.py", line 720, in urlopen
    method, url, error=e, _pool=self, _stacktrace=sys.exc_info()[2]
  File "/home/zyf0717/anaconda3/envs/crawl/lib/python3.7/site-packages/urllib3/util/retry.py", line 436, in increment
    raise MaxRetryError(_pool, url, error or ResponseError(cause))
urllib3.exceptions.MaxRetryError: HTTPSConnectionPool(host='gateway.watsonplatform.net', port=443): Max retries exceeded with url: /natural-language-understanding/api/v1/analyze?version=2019-07-12/v1/analyze&version=2019-07-12 (Caused by NewConnectionError('<urllib3.connection.VerifiedHTTPSConnection object at 0x7fc44ac9cb90>: Failed to establish a new connection: [Errno -3] Temporary failure in name resolution'))

During handling of the above exception, another exception occurred:

Traceback (most recent call last):
  File "/home/zyf0717/git/STB_social_media_analytics/tripadvisor/sentiment_scorer.py", line 179, in score_sentiments_1_poi
    self.get_api_response()
  File "/home/zyf0717/git/STB_social_media_analytics/tripadvisor/sentiment_scorer.py", line 239, in get_api_response
    keywords=KeywordsOptions(emotion=True, sentiment=True, limit=10000)
  File "/home/zyf0717/anaconda3/envs/crawl/lib/python3.7/site-packages/ibm_watson/natural_language_understanding_v1.py", line 186, in analyze
    response = self.send(request)
  File "/home/zyf0717/anaconda3/envs/crawl/lib/python3.7/site-packages/ibm_cloud_sdk_core/base_service.py", line 136, in send
    response = requests.request(**request, cookies=self.jar, **kwargs)
  File "/home/zyf0717/anaconda3/envs/crawl/lib/python3.7/site-packages/requests/api.py", line 60, in request
    return session.request(method=method, url=url, **kwargs)
  File "/home/zyf0717/anaconda3/envs/crawl/lib/python3.7/site-packages/requests/sessions.py", line 533, in request
    resp = self.send(prep, **send_kwargs)
  File "/home/zyf0717/anaconda3/envs/crawl/lib/python3.7/site-packages/requests/sessions.py", line 646, in send
    r = adapter.send(request, **kwargs)
  File "/home/zyf0717/anaconda3/envs/crawl/lib/python3.7/site-packages/requests/adapters.py", line 516, in send
    raise ConnectionError(e, request=request)
requests.exceptions.ConnectionError: HTTPSConnectionPool(host='gateway.watsonplatform.net', port=443): Max retries exceeded with url: /natural-language-understanding/api/v1/analyze?version=2019-07-12/v1/analyze&version=2019-07-12 (Caused by NewConnectionError('<urllib3.connection.VerifiedHTTPSConnection object at 0x7fc44ac9cb90>: Failed to establish a new connection: [Errno -3] Temporary failure in name resolution'))

Error in API call.
POI index: 12, review ID: 601969980, row index: 1074, time: 2020-02-09 01:49:39.899122
Traceback (most recent call last):
  File "/home/zyf0717/anaconda3/envs/crawl/lib/python3.7/site-packages/urllib3/connection.py", line 157, in _new_conn
    (self._dns_host, self.port), self.timeout, **extra_kw
  File "/home/zyf0717/anaconda3/envs/crawl/lib/python3.7/site-packages/urllib3/util/connection.py", line 61, in create_connection
    for res in socket.getaddrinfo(host, port, family, socket.SOCK_STREAM):
  File "/home/zyf0717/anaconda3/envs/crawl/lib/python3.7/socket.py", line 748, in getaddrinfo
    for res in _socket.getaddrinfo(host, port, family, type, proto, flags):
socket.gaierror: [Errno -3] Temporary failure in name resolution

During handling of the above exception, another exception occurred:

Traceback (most recent call last):
  File "/home/zyf0717/anaconda3/envs/crawl/lib/python3.7/site-packages/urllib3/connectionpool.py", line 672, in urlopen
    chunked=chunked,
  File "/home/zyf0717/anaconda3/envs/crawl/lib/python3.7/site-packages/urllib3/connectionpool.py", line 376, in _make_request
    self._validate_conn(conn)
  File "/home/zyf0717/anaconda3/envs/crawl/lib/python3.7/site-packages/urllib3/connectionpool.py", line 994, in _validate_conn
    conn.connect()
  File "/home/zyf0717/anaconda3/envs/crawl/lib/python3.7/site-packages/urllib3/connection.py", line 334, in connect
    conn = self._new_conn()
  File "/home/zyf0717/anaconda3/envs/crawl/lib/python3.7/site-packages/urllib3/connection.py", line 169, in _new_conn
    self, "Failed to establish a new connection: %s" % e
urllib3.exceptions.NewConnectionError: <urllib3.connection.VerifiedHTTPSConnection object at 0x7fc44ac67990>: Failed to establish a new connection: [Errno -3] Temporary failure in name resolution

During handling of the above exception, another exception occurred:

Traceback (most recent call last):
  File "/home/zyf0717/anaconda3/envs/crawl/lib/python3.7/site-packages/requests/adapters.py", line 449, in send
    timeout=timeout
  File "/home/zyf0717/anaconda3/envs/crawl/lib/python3.7/site-packages/urllib3/connectionpool.py", line 720, in urlopen
    method, url, error=e, _pool=self, _stacktrace=sys.exc_info()[2]
  File "/home/zyf0717/anaconda3/envs/crawl/lib/python3.7/site-packages/urllib3/util/retry.py", line 436, in increment
    raise MaxRetryError(_pool, url, error or ResponseError(cause))
urllib3.exceptions.MaxRetryError: HTTPSConnectionPool(host='gateway.watsonplatform.net', port=443): Max retries exceeded with url: /natural-language-understanding/api/v1/analyze?version=2019-07-12/v1/analyze&version=2019-07-12 (Caused by NewConnectionError('<urllib3.connection.VerifiedHTTPSConnection object at 0x7fc44ac67990>: Failed to establish a new connection: [Errno -3] Temporary failure in name resolution'))

During handling of the above exception, another exception occurred:

Traceback (most recent call last):
  File "/home/zyf0717/git/STB_social_media_analytics/tripadvisor/sentiment_scorer.py", line 179, in score_sentiments_1_poi
    self.get_api_response()
  File "/home/zyf0717/git/STB_social_media_analytics/tripadvisor/sentiment_scorer.py", line 239, in get_api_response
    keywords=KeywordsOptions(emotion=True, sentiment=True, limit=10000)
  File "/home/zyf0717/anaconda3/envs/crawl/lib/python3.7/site-packages/ibm_watson/natural_language_understanding_v1.py", line 186, in analyze
    response = self.send(request)
  File "/home/zyf0717/anaconda3/envs/crawl/lib/python3.7/site-packages/ibm_cloud_sdk_core/base_service.py", line 136, in send
    response = requests.request(**request, cookies=self.jar, **kwargs)
  File "/home/zyf0717/anaconda3/envs/crawl/lib/python3.7/site-packages/requests/api.py", line 60, in request
    return session.request(method=method, url=url, **kwargs)
  File "/home/zyf0717/anaconda3/envs/crawl/lib/python3.7/site-packages/requests/sessions.py", line 533, in request
    resp = self.send(prep, **send_kwargs)
  File "/home/zyf0717/anaconda3/envs/crawl/lib/python3.7/site-packages/requests/sessions.py", line 646, in send
    r = adapter.send(request, **kwargs)
  File "/home/zyf0717/anaconda3/envs/crawl/lib/python3.7/site-packages/requests/adapters.py", line 516, in send
    raise ConnectionError(e, request=request)
requests.exceptions.ConnectionError: HTTPSConnectionPool(host='gateway.watsonplatform.net', port=443): Max retries exceeded with url: /natural-language-understanding/api/v1/analyze?version=2019-07-12/v1/analyze&version=2019-07-12 (Caused by NewConnectionError('<urllib3.connection.VerifiedHTTPSConnection object at 0x7fc44ac67990>: Failed to establish a new connection: [Errno -3] Temporary failure in name resolution'))

Error in API call.
POI index: 15, review ID: 576704398, row index: 207, time: 2020-02-09 02:03:28.418451
Traceback (most recent call last):
  File "/home/zyf0717/git/STB_social_media_analytics/tripadvisor/sentiment_scorer.py", line 179, in score_sentiments_1_poi
    self.get_api_response()
  File "/home/zyf0717/git/STB_social_media_analytics/tripadvisor/sentiment_scorer.py", line 239, in get_api_response
    keywords=KeywordsOptions(emotion=True, sentiment=True, limit=10000)
  File "/home/zyf0717/anaconda3/envs/crawl/lib/python3.7/site-packages/ibm_watson/natural_language_understanding_v1.py", line 186, in analyze
    response = self.send(request)
  File "/home/zyf0717/anaconda3/envs/crawl/lib/python3.7/site-packages/ibm_cloud_sdk_core/base_service.py", line 157, in send
    response.status_code, error_message, http_response=response)
ibm_cloud_sdk_core.api_exception.ApiException: Error: <HTML><HEAD>
<TITLE>Service Unavailable</TITLE>
</HEAD><BODY>
<H1>Service Unavailable - Zero size object</H1>
The server is temporarily unable to service your request.  Please try again
later.<P>
Reference&#32;&#35;15&#46;4e76d317&#46;1581185008&#46;ac254c0
</BODY></HTML>
, Code: 503

Error in API call.
POI index: 18, review ID: 732674453, row index: 5, time: 2020-02-09 03:37:06.216546
Traceback (most recent call last):
  File "/home/zyf0717/git/STB_social_media_analytics/tripadvisor/sentiment_scorer.py", line 179, in score_sentiments_1_poi
    self.get_api_response()
  File "/home/zyf0717/git/STB_social_media_analytics/tripadvisor/sentiment_scorer.py", line 239, in get_api_response
    keywords=KeywordsOptions(emotion=True, sentiment=True, limit=10000)
  File "/home/zyf0717/anaconda3/envs/crawl/lib/python3.7/site-packages/ibm_watson/natural_language_understanding_v1.py", line 186, in analyze
    response = self.send(request)
  File "/home/zyf0717/anaconda3/envs/crawl/lib/python3.7/site-packages/ibm_cloud_sdk_core/base_service.py", line 157, in send
    response.status_code, error_message, http_response=response)
ibm_cloud_sdk_core.api_exception.ApiException: Error: unsupported text language: pl, Code: 400 , X-global-transaction-id: 34d3a886f8847aa4199b026e082df46b

Error in API call.
POI index: 19, review ID: 494480247, row index: 103, time: 2020-02-09 04:28:50.181453
Traceback (most recent call last):
  File "/home/zyf0717/git/STB_social_media_analytics/tripadvisor/sentiment_scorer.py", line 179, in score_sentiments_1_poi
    self.get_api_response()
  File "/home/zyf0717/git/STB_social_media_analytics/tripadvisor/sentiment_scorer.py", line 239, in get_api_response
    keywords=KeywordsOptions(emotion=True, sentiment=True, limit=10000)
  File "/home/zyf0717/anaconda3/envs/crawl/lib/python3.7/site-packages/ibm_watson/natural_language_understanding_v1.py", line 186, in analyze
    response = self.send(request)
  File "/home/zyf0717/anaconda3/envs/crawl/lib/python3.7/site-packages/ibm_cloud_sdk_core/base_service.py", line 157, in send
    response.status_code, error_message, http_response=response)
ibm_cloud_sdk_core.api_exception.ApiException: Error: unsupported text language: fa, Code: 400 , X-global-transaction-id: bf020d1ef281a093d32fac2a40e50268

Error in API call.
POI index: 20, review ID: 443892721, row index: 598, time: 2020-02-09 04:54:36.469858
Traceback (most recent call last):
  File "/home/zyf0717/git/STB_social_media_analytics/tripadvisor/sentiment_scorer.py", line 179, in score_sentiments_1_poi
    self.get_api_response()
  File "/home/zyf0717/git/STB_social_media_analytics/tripadvisor/sentiment_scorer.py", line 239, in get_api_response
    keywords=KeywordsOptions(emotion=True, sentiment=True, limit=10000)
  File "/home/zyf0717/anaconda3/envs/crawl/lib/python3.7/site-packages/ibm_watson/natural_language_understanding_v1.py", line 186, in analyze
    response = self.send(request)
  File "/home/zyf0717/anaconda3/envs/crawl/lib/python3.7/site-packages/ibm_cloud_sdk_core/base_service.py", line 157, in send
    response.status_code, error_message, http_response=response)
ibm_cloud_sdk_core.api_exception.ApiException: Error: unsupported text language: id, Code: 400 , X-global-transaction-id: 328fdb87f1524ac48132b5368a5ba6c0

