2, 
新加坡环球影城
  
, page: 1, 2020-01-31 09:38:49.494604
Traceback (most recent call last):
  File "/home/jia/Desktop/git/STB_social_media_analytics/experimentation/jiaxin_experiment/QY/QY_crawler.py", line 190, in crawl_info
    self.crawl_reviews()
  File "/home/jia/Desktop/git/STB_social_media_analytics/experimentation/jiaxin_experiment/QY/QY_crawler.py", line 312, in crawl_reviews
    self.crawl_reviews_1_page(self.current_poi_index)
  File "/home/jia/Desktop/git/STB_social_media_analytics/experimentation/jiaxin_experiment/QY/QY_crawler.py", line 402, in crawl_reviews_1_page
    next_page_button = self.driver.find_elements_by_xpath('//a[@title="下一页"]')
  File "/home/jia/anaconda3/envs/crawl/lib/python3.7/site-packages/selenium/webdriver/remote/webdriver.py", line 410, in find_elements_by_xpath
    return self.find_elements(by=By.XPATH, value=xpath)
  File "/home/jia/anaconda3/envs/crawl/lib/python3.7/site-packages/selenium/webdriver/remote/webdriver.py", line 1007, in find_elements
    'value': value})['value'] or []
  File "/home/jia/anaconda3/envs/crawl/lib/python3.7/site-packages/selenium/webdriver/remote/webdriver.py", line 321, in execute
    self.error_handler.check_response(response)
  File "/home/jia/anaconda3/envs/crawl/lib/python3.7/site-packages/selenium/webdriver/remote/errorhandler.py", line 242, in check_response
    raise exception_class(message, screen, stacktrace)
selenium.common.exceptions.WebDriverException: Message: chrome not reachable
  (Session info: chrome=79.0.3945.130)


